Unhandled exception in internal background task 'checkEnergyQuest'.
Traceback (most recent call last):
  File "/home/conard/.local/lib/python3.6/site-packages/discord/ext/tasks/__init__.py", line 101, in _loop
    await self.coro(*args, **kwargs)
  File "Bot.py", line 125, in checkEnergyQuest
    print("in cron, " + forceAlert + ", " + alertPing)
TypeError: must be str, not bool
Task exception was never retrieved
future: <Task finished coro=<Loop._loop() done, defined at /home/conard/.local/lib/python3.6/site-packages/discord/ext/tasks/__init__.py:88> exception=TypeError('must be str, not bool',)>
Traceback (most recent call last):
  File "/home/conard/.local/lib/python3.6/site-packages/discord/ext/tasks/__init__.py", line 125, in _loop
    raise exc
  File "/home/conard/.local/lib/python3.6/site-packages/discord/ext/tasks/__init__.py", line 101, in _loop
    await self.coro(*args, **kwargs)
  File "Bot.py", line 125, in checkEnergyQuest
    try:
TypeError: must be str, not bool
